[2024-06-20T09:37:42.538+0000] {local_task_job_runner.py:120} INFO - ::group::Pre task execution logs
[2024-06-20T09:37:42.565+0000] {taskinstance.py:2076} INFO - Dependencies all met for dep_context=non-requeueable deps ti=<TaskInstance: ELT-PROJECT.transform.fact_order_details.test manual__2024-06-20T09:32:39.273282+00:00 [queued]>
[2024-06-20T09:37:42.579+0000] {taskinstance.py:2076} INFO - Dependencies all met for dep_context=requeueable deps ti=<TaskInstance: ELT-PROJECT.transform.fact_order_details.test manual__2024-06-20T09:32:39.273282+00:00 [queued]>
[2024-06-20T09:37:42.580+0000] {taskinstance.py:2306} INFO - Starting attempt 1 of 2
[2024-06-20T09:37:42.596+0000] {taskinstance.py:2330} INFO - Executing <Task(DbtTestLocalOperator): transform.fact_order_details.test> on 2024-06-20 09:32:39.273282+00:00
[2024-06-20T09:37:42.604+0000] {logging_mixin.py:188} WARNING - /home/airflow/.local/lib/python3.12/site-packages/airflow/task/task_runner/standard_task_runner.py:61 DeprecationWarning: This process (pid=7187) is multi-threaded, use of fork() may lead to deadlocks in the child.
[2024-06-20T09:37:42.605+0000] {standard_task_runner.py:63} INFO - Started process 7189 to run task
[2024-06-20T09:37:42.604+0000] {standard_task_runner.py:90} INFO - Running: ['airflow', 'tasks', 'run', 'ELT-PROJECT', 'transform.fact_order_details.test', 'manual__2024-06-20T09:32:39.273282+00:00', '--job-id', '441', '--raw', '--subdir', 'DAGS_FOLDER/elt.py', '--cfg-path', '/tmp/tmpqe7l2mtl']
[2024-06-20T09:37:42.607+0000] {standard_task_runner.py:91} INFO - Job 441: Subtask transform.fact_order_details.test
[2024-06-20T09:37:42.626+0000] {logging_mixin.py:188} WARNING - /home/airflow/.local/lib/python3.12/site-packages/airflow/settings.py:195 DeprecationWarning: The sql_alchemy_conn option in [core] has been moved to the sql_alchemy_conn option in [database] - the old setting has been used, but please update your config.
[2024-06-20T09:37:42.672+0000] {task_command.py:426} INFO - Running <TaskInstance: ELT-PROJECT.transform.fact_order_details.test manual__2024-06-20T09:32:39.273282+00:00 [running]> on host airflow-scheduler
[2024-06-20T09:37:42.811+0000] {taskinstance.py:2648} INFO - Exporting env vars: AIRFLOW_CTX_DAG_OWNER='Data-Ninja' AIRFLOW_CTX_DAG_ID='ELT-PROJECT' AIRFLOW_CTX_TASK_ID='transform.fact_order_details.test' AIRFLOW_CTX_EXECUTION_DATE='2024-06-20T09:32:39.273282+00:00' AIRFLOW_CTX_TRY_NUMBER='1' AIRFLOW_CTX_DAG_RUN_ID='manual__2024-06-20T09:32:39.273282+00:00'
[2024-06-20T09:37:42.812+0000] {taskinstance.py:430} INFO - ::endgroup::
[2024-06-20T09:37:42.827+0000] {local.py:174} INFO - Could not import dbtRunner. Falling back to subprocess for invoking dbt.
[2024-06-20T09:37:42.829+0000] {local.py:292} INFO - Cloning project to writable temp directory /tmp/tmp82w8kpxv from /opt/airflow/dags/dbt/dbt_project
[2024-06-20T09:37:42.839+0000] {local.py:303} INFO - Partial parse is enabled and the latest partial parse file is /tmp/cosmos/ELT-PROJECT__transform/target/partial_parse.msgpack
[2024-06-20T09:37:42.864+0000] {base.py:84} INFO - Using connection ID 'snow_conn' for task execution.
[2024-06-20T09:37:42.865+0000] {crypto.py:82} WARNING - empty cryptography key - values will not be stored encrypted.
[2024-06-20T09:37:42.867+0000] {base.py:225} INFO - Using real values for profile dbt_project
[2024-06-20T09:37:42.869+0000] {config.py:291} INFO - Creating temporary profiles.yml with use_mock_values=False at /tmp/tmp55st49k3/profiles.yml with the following contents:
dbt_project:
    outputs:
        dev:
            account: sk84886.europe-west2.gcp
            database: ELT_PROJECT
            password: '{{ env_var(''COSMOS_CONN_SNOWFLAKE_PASSWORD'') }}'
            role: SYSADMIN
            schema: PUBLIC
            type: snowflake
            user: DATANINJA
            warehouse: TRANSFORM
    target: dev

[2024-06-20T09:37:42.871+0000] {local.py:247} INFO - Trying to run the command:
 ['/opt/airflow/dbt_venv/bin/dbt', 'deps', '--project-dir', '/tmp/tmp82w8kpxv', '--profiles-dir', '/tmp/tmp55st49k3', '--profile', 'dbt_project', '--target', 'dev']
From /tmp/tmp82w8kpxv
[2024-06-20T09:37:42.872+0000] {subprocess.py:60} INFO - Tmp dir root location: 
 /tmp
[2024-06-20T09:37:42.873+0000] {subprocess.py:73} INFO - Running command: ['/opt/airflow/dbt_venv/bin/dbt', 'deps', '--project-dir', '/tmp/tmp82w8kpxv', '--profiles-dir', '/tmp/tmp55st49k3', '--profile', 'dbt_project', '--target', 'dev']
[2024-06-20T09:37:42.886+0000] {subprocess.py:84} INFO - Command output:
[2024-06-20T09:37:44.962+0000] {subprocess.py:94} INFO - [0m09:37:44  Running with dbt=1.8.2
[2024-06-20T09:37:45.196+0000] {subprocess.py:94} INFO - [0m09:37:45  Updating lock file in file path: /tmp/tmp82w8kpxv/package-lock.yml
[2024-06-20T09:37:45.205+0000] {subprocess.py:94} INFO - [0m09:37:45  Installing dbt-labs/dbt_utils
[2024-06-20T09:37:45.701+0000] {subprocess.py:94} INFO - [0m09:37:45  Installed from version 0.8.6
[2024-06-20T09:37:45.701+0000] {subprocess.py:94} INFO - [0m09:37:45  Updated version available: 1.2.0
[2024-06-20T09:37:45.703+0000] {subprocess.py:94} INFO - [0m09:37:45
[2024-06-20T09:37:45.704+0000] {subprocess.py:94} INFO - [0m09:37:45  Updates available for packages: ['dbt-labs/dbt_utils']
[2024-06-20T09:37:45.705+0000] {subprocess.py:94} INFO - Update your versions in packages.yml, then run dbt deps
[2024-06-20T09:37:47.711+0000] {subprocess.py:98} INFO - Command exited with return code 0
[2024-06-20T09:37:47.712+0000] {local.py:254} INFO - Update your versions in packages.yml, then run dbt deps
[2024-06-20T09:37:47.713+0000] {local.py:247} INFO - Trying to run the command:
 ['/opt/airflow/dbt_venv/bin/dbt', 'test', '--models', 'fact_order_details', '--project-dir', '/tmp/tmp82w8kpxv', '--profiles-dir', '/tmp/tmp55st49k3', '--profile', 'dbt_project', '--target', 'dev']
From /tmp/tmp82w8kpxv
[2024-06-20T09:37:47.714+0000] {subprocess.py:60} INFO - Tmp dir root location: 
 /tmp
[2024-06-20T09:37:47.715+0000] {subprocess.py:73} INFO - Running command: ['/opt/airflow/dbt_venv/bin/dbt', 'test', '--models', 'fact_order_details', '--project-dir', '/tmp/tmp82w8kpxv', '--profiles-dir', '/tmp/tmp55st49k3', '--profile', 'dbt_project', '--target', 'dev']
[2024-06-20T09:37:47.729+0000] {subprocess.py:84} INFO - Command output:
[2024-06-20T09:37:50.184+0000] {subprocess.py:94} INFO - [0m09:37:50  Running with dbt=1.8.2
[2024-06-20T09:37:50.868+0000] {subprocess.py:94} INFO - [0m09:37:50  Registered adapter: snowflake=1.8.3
[2024-06-20T09:37:52.124+0000] {subprocess.py:94} INFO - [0m09:37:52  Found 20 models, 30 data tests, 11 sources, 682 macros
[2024-06-20T09:37:52.128+0000] {subprocess.py:94} INFO - [0m09:37:52
[2024-06-20T09:37:57.460+0000] {subprocess.py:94} INFO - [0m09:37:57  Concurrency: 1 threads (target='dev')
[2024-06-20T09:37:57.462+0000] {subprocess.py:94} INFO - [0m09:37:57
[2024-06-20T09:37:57.479+0000] {subprocess.py:94} INFO - [0m09:37:57  1 of 6 START test not_null_fact_order_details_ORDERDETAILID .................... [RUN]
[2024-06-20T09:37:59.393+0000] {subprocess.py:94} INFO - [0m09:37:59  1 of 6 PASS not_null_fact_order_details_ORDERDETAILID .......................... [[32mPASS[0m in 1.91s]
[2024-06-20T09:37:59.399+0000] {subprocess.py:94} INFO - [0m09:37:59  2 of 6 START test not_null_fact_order_details_ORDERID .......................... [RUN]
[2024-06-20T09:38:00.996+0000] {subprocess.py:94} INFO - [0m09:38:00  2 of 6 PASS not_null_fact_order_details_ORDERID ................................ [[32mPASS[0m in 1.59s]
[2024-06-20T09:38:01.004+0000] {subprocess.py:94} INFO - [0m09:38:01  3 of 6 START test not_null_fact_order_details_PRODUCTID ........................ [RUN]
[2024-06-20T09:38:02.951+0000] {subprocess.py:94} INFO - [0m09:38:02  3 of 6 PASS not_null_fact_order_details_PRODUCTID .............................. [[32mPASS[0m in 1.95s]
[2024-06-20T09:38:02.956+0000] {subprocess.py:94} INFO - [0m09:38:02  4 of 6 START test unique_fact_order_details_ORDERDETAILID ...................... [RUN]
[2024-06-20T09:38:04.932+0000] {subprocess.py:94} INFO - [0m09:38:04  4 of 6 FAIL 693 unique_fact_order_details_ORDERDETAILID ........................ [[31mFAIL 693[0m in 1.97s]
[2024-06-20T09:38:04.937+0000] {subprocess.py:94} INFO - [0m09:38:04  5 of 6 START test unique_fact_order_details_ORDERID ............................ [RUN]
[2024-06-20T09:38:07.498+0000] {subprocess.py:94} INFO - [0m09:38:07  5 of 6 FAIL 693 unique_fact_order_details_ORDERID .............................. [[31mFAIL 693[0m in 2.56s]
[2024-06-20T09:38:07.502+0000] {subprocess.py:94} INFO - [0m09:38:07  6 of 6 START test unique_fact_order_details_PRODUCTID .......................... [RUN]
[2024-06-20T09:38:09.100+0000] {subprocess.py:94} INFO - [0m09:38:09  6 of 6 FAIL 77 unique_fact_order_details_PRODUCTID ............................. [[31mFAIL 77[0m in 1.60s]
[2024-06-20T09:38:09.107+0000] {subprocess.py:94} INFO - [0m09:38:09
[2024-06-20T09:38:09.108+0000] {subprocess.py:94} INFO - [0m09:38:09  Finished running 6 data tests in 0 hours 0 minutes and 16.98 seconds (16.98s).
[2024-06-20T09:38:09.191+0000] {subprocess.py:94} INFO - [0m09:38:09
[2024-06-20T09:38:09.192+0000] {subprocess.py:94} INFO - [0m09:38:09  [31mCompleted with 3 errors and 0 warnings:[0m
[2024-06-20T09:38:09.194+0000] {subprocess.py:94} INFO - [0m09:38:09
[2024-06-20T09:38:09.195+0000] {subprocess.py:94} INFO - [0m09:38:09  [31mFailure in test unique_fact_order_details_ORDERDETAILID (models/warehouse/schema.yml)[0m
[2024-06-20T09:38:09.197+0000] {subprocess.py:94} INFO - [0m09:38:09    Got 693 results, configured to fail if != 0
[2024-06-20T09:38:09.199+0000] {subprocess.py:94} INFO - [0m09:38:09
[2024-06-20T09:38:09.201+0000] {subprocess.py:94} INFO - [0m09:38:09    compiled code at target/compiled/dbt_project/models/warehouse/schema.yml/unique_fact_order_details_ORDERDETAILID.sql
[2024-06-20T09:38:09.202+0000] {subprocess.py:94} INFO - [0m09:38:09
[2024-06-20T09:38:09.203+0000] {subprocess.py:94} INFO - [0m09:38:09  [31mFailure in test unique_fact_order_details_ORDERID (models/warehouse/schema.yml)[0m
[2024-06-20T09:38:09.205+0000] {subprocess.py:94} INFO - [0m09:38:09    Got 693 results, configured to fail if != 0
[2024-06-20T09:38:09.206+0000] {subprocess.py:94} INFO - [0m09:38:09
[2024-06-20T09:38:09.208+0000] {subprocess.py:94} INFO - [0m09:38:09    compiled code at target/compiled/dbt_project/models/warehouse/schema.yml/unique_fact_order_details_ORDERID.sql
[2024-06-20T09:38:09.209+0000] {subprocess.py:94} INFO - [0m09:38:09
[2024-06-20T09:38:09.211+0000] {subprocess.py:94} INFO - [0m09:38:09  [31mFailure in test unique_fact_order_details_PRODUCTID (models/warehouse/schema.yml)[0m
[2024-06-20T09:38:09.215+0000] {subprocess.py:94} INFO - [0m09:38:09    Got 77 results, configured to fail if != 0
[2024-06-20T09:38:09.216+0000] {subprocess.py:94} INFO - [0m09:38:09
[2024-06-20T09:38:09.218+0000] {subprocess.py:94} INFO - [0m09:38:09    compiled code at target/compiled/dbt_project/models/warehouse/schema.yml/unique_fact_order_details_PRODUCTID.sql
[2024-06-20T09:38:09.219+0000] {subprocess.py:94} INFO - [0m09:38:09
[2024-06-20T09:38:09.221+0000] {subprocess.py:94} INFO - [0m09:38:09  Done. PASS=3 WARN=0 ERROR=3 SKIP=0 TOTAL=6
[2024-06-20T09:38:10.768+0000] {subprocess.py:98} INFO - Command exited with return code 1
[2024-06-20T09:38:10.769+0000] {local.py:254} INFO - [0m09:38:09  Done. PASS=3 WARN=0 ERROR=3 SKIP=0 TOTAL=6
[2024-06-20T09:38:10.793+0000] {local.py:196} WARNING - Artifact schema version: https://schemas.getdbt.com/dbt/manifest/v12.json is above dbt-ol supported version 7. This might cause errors.
[2024-06-20T09:38:10.794+0000] {local.py:196} WARNING - Artifact schema version: https://schemas.getdbt.com/dbt/run-results/v6.json is above dbt-ol supported version 5. This might cause errors.
[2024-06-20T09:38:10.801+0000] {local.py:349} INFO - Inlets: [Dataset(uri='snowflake://sk84886.europe-west2.gcp/ELT_PROJECT.dwh.fact_order_details', extra=None)]
[2024-06-20T09:38:10.802+0000] {local.py:350} INFO - Outlets: []
[2024-06-20T09:38:10.803+0000] {dag.py:3096} INFO - Sync 1 DAGs
[2024-06-20T09:38:11.038+0000] {dag.py:3954} INFO - Setting next_dagrun for ELT-PROJECT to None, run_after=None
[2024-06-20T09:38:11.082+0000] {local.py:184} ERROR - [0m09:37:50  Running with dbt=1.8.2
[0m09:37:50  Registered adapter: snowflake=1.8.3
[0m09:37:52  Found 20 models, 30 data tests, 11 sources, 682 macros
[0m09:37:52
[0m09:37:57  Concurrency: 1 threads (target='dev')
[0m09:37:57
[0m09:37:57  1 of 6 START test not_null_fact_order_details_ORDERDETAILID .................... [RUN]
[0m09:37:59  1 of 6 PASS not_null_fact_order_details_ORDERDETAILID .......................... [[32mPASS[0m in 1.91s]
[0m09:37:59  2 of 6 START test not_null_fact_order_details_ORDERID .......................... [RUN]
[0m09:38:00  2 of 6 PASS not_null_fact_order_details_ORDERID ................................ [[32mPASS[0m in 1.59s]
[0m09:38:01  3 of 6 START test not_null_fact_order_details_PRODUCTID ........................ [RUN]
[0m09:38:02  3 of 6 PASS not_null_fact_order_details_PRODUCTID .............................. [[32mPASS[0m in 1.95s]
[0m09:38:02  4 of 6 START test unique_fact_order_details_ORDERDETAILID ...................... [RUN]
[0m09:38:04  4 of 6 FAIL 693 unique_fact_order_details_ORDERDETAILID ........................ [[31mFAIL 693[0m in 1.97s]
[0m09:38:04  5 of 6 START test unique_fact_order_details_ORDERID ............................ [RUN]
[0m09:38:07  5 of 6 FAIL 693 unique_fact_order_details_ORDERID .............................. [[31mFAIL 693[0m in 2.56s]
[0m09:38:07  6 of 6 START test unique_fact_order_details_PRODUCTID .......................... [RUN]
[0m09:38:09  6 of 6 FAIL 77 unique_fact_order_details_PRODUCTID ............................. [[31mFAIL 77[0m in 1.60s]
[0m09:38:09
[0m09:38:09  Finished running 6 data tests in 0 hours 0 minutes and 16.98 seconds (16.98s).
[0m09:38:09
[0m09:38:09  [31mCompleted with 3 errors and 0 warnings:[0m
[0m09:38:09
[0m09:38:09  [31mFailure in test unique_fact_order_details_ORDERDETAILID (models/warehouse/schema.yml)[0m
[0m09:38:09    Got 693 results, configured to fail if != 0
[0m09:38:09
[0m09:38:09    compiled code at target/compiled/dbt_project/models/warehouse/schema.yml/unique_fact_order_details_ORDERDETAILID.sql
[0m09:38:09
[0m09:38:09  [31mFailure in test unique_fact_order_details_ORDERID (models/warehouse/schema.yml)[0m
[0m09:38:09    Got 693 results, configured to fail if != 0
[0m09:38:09
[0m09:38:09    compiled code at target/compiled/dbt_project/models/warehouse/schema.yml/unique_fact_order_details_ORDERID.sql
[0m09:38:09
[0m09:38:09  [31mFailure in test unique_fact_order_details_PRODUCTID (models/warehouse/schema.yml)[0m
[0m09:38:09    Got 77 results, configured to fail if != 0
[0m09:38:09
[0m09:38:09    compiled code at target/compiled/dbt_project/models/warehouse/schema.yml/unique_fact_order_details_PRODUCTID.sql
[0m09:38:09
[0m09:38:09  Done. PASS=3 WARN=0 ERROR=3 SKIP=0 TOTAL=6
[2024-06-20T09:38:11.104+0000] {taskinstance.py:441} INFO - ::group::Post task execution logs
[2024-06-20T09:38:11.120+0000] {taskinstance.py:2905} ERROR - Task failed with exception
Traceback (most recent call last):
  File "/home/airflow/.local/lib/python3.12/site-packages/airflow/models/taskinstance.py", line 465, in _execute_task
    result = _execute_callable(context=context, **execute_callable_kwargs)
             ^^^^^^^^^^^^^^^^^^^^^^^^^^^^^^^^^^^^^^^^^^^^^^^^^^^^^^^^^^^^^
  File "/home/airflow/.local/lib/python3.12/site-packages/airflow/models/taskinstance.py", line 432, in _execute_callable
    return execute_callable(context=context, **execute_callable_kwargs)
           ^^^^^^^^^^^^^^^^^^^^^^^^^^^^^^^^^^^^^^^^^^^^^^^^^^^^^^^^^^^^
  File "/home/airflow/.local/lib/python3.12/site-packages/airflow/models/baseoperator.py", line 401, in wrapper
    return func(self, *args, **kwargs)
           ^^^^^^^^^^^^^^^^^^^^^^^^^^^
  File "/home/airflow/.local/lib/python3.12/site-packages/cosmos/operators/local.py", line 579, in execute
    result = self.build_and_run_cmd(context=context, cmd_flags=self.add_cmd_flags())
             ^^^^^^^^^^^^^^^^^^^^^^^^^^^^^^^^^^^^^^^^^^^^^^^^^^^^^^^^^^^^^^^^^^^^^^^
  File "/home/airflow/.local/lib/python3.12/site-packages/cosmos/operators/local.py", line 489, in build_and_run_cmd
    result = self.run_command(cmd=dbt_cmd, env=env, context=context)
             ^^^^^^^^^^^^^^^^^^^^^^^^^^^^^^^^^^^^^^^^^^^^^^^^^^^^^^^
  File "/home/airflow/.local/lib/python3.12/site-packages/cosmos/operators/local.py", line 359, in run_command
    self.handle_exception(result)
  File "/home/airflow/.local/lib/python3.12/site-packages/cosmos/operators/local.py", line 185, in handle_exception_subprocess
    raise AirflowException(f"dbt command failed. The command returned a non-zero exit code {result.exit_code}.")
airflow.exceptions.AirflowException: dbt command failed. The command returned a non-zero exit code 1.
[2024-06-20T09:38:11.127+0000] {taskinstance.py:1206} INFO - Marking task as UP_FOR_RETRY. dag_id=ELT-PROJECT, task_id=transform.fact_order_details.test, run_id=manual__2024-06-20T09:32:39.273282+00:00, execution_date=20240620T093239, start_date=20240620T093742, end_date=20240620T093811
[2024-06-20T09:38:11.144+0000] {standard_task_runner.py:110} ERROR - Failed to execute job 441 for task transform.fact_order_details.test (dbt command failed. The command returned a non-zero exit code 1.; 7189)
[2024-06-20T09:38:11.199+0000] {local_task_job_runner.py:240} INFO - Task exited with return code 1
[2024-06-20T09:38:11.264+0000] {taskinstance.py:3503} INFO - 0 downstream tasks scheduled from follow-on schedule check
[2024-06-20T09:38:11.268+0000] {local_task_job_runner.py:222} INFO - ::endgroup::
