[2024-06-20T09:49:58.120+0000] {local_task_job_runner.py:120} INFO - ::group::Pre task execution logs
[2024-06-20T09:49:58.153+0000] {taskinstance.py:2076} INFO - Dependencies all met for dep_context=non-requeueable deps ti=<TaskInstance: ELT-PROJECT.transform.fact_order_details.test manual__2024-06-20T09:44:25.931260+00:00 [queued]>
[2024-06-20T09:49:58.169+0000] {taskinstance.py:2076} INFO - Dependencies all met for dep_context=requeueable deps ti=<TaskInstance: ELT-PROJECT.transform.fact_order_details.test manual__2024-06-20T09:44:25.931260+00:00 [queued]>
[2024-06-20T09:49:58.169+0000] {taskinstance.py:2306} INFO - Starting attempt 1 of 2
[2024-06-20T09:49:58.194+0000] {taskinstance.py:2330} INFO - Executing <Task(DbtTestLocalOperator): transform.fact_order_details.test> on 2024-06-20 09:44:25.931260+00:00
[2024-06-20T09:49:58.204+0000] {logging_mixin.py:188} WARNING - /home/airflow/.local/lib/python3.12/site-packages/airflow/task/task_runner/standard_task_runner.py:61 DeprecationWarning: This process (pid=8187) is multi-threaded, use of fork() may lead to deadlocks in the child.
[2024-06-20T09:49:58.205+0000] {standard_task_runner.py:63} INFO - Started process 8189 to run task
[2024-06-20T09:49:58.204+0000] {standard_task_runner.py:90} INFO - Running: ['airflow', 'tasks', 'run', 'ELT-PROJECT', 'transform.fact_order_details.test', 'manual__2024-06-20T09:44:25.931260+00:00', '--job-id', '498', '--raw', '--subdir', 'DAGS_FOLDER/elt.py', '--cfg-path', '/tmp/tmpu7ikjjba']
[2024-06-20T09:49:58.208+0000] {standard_task_runner.py:91} INFO - Job 498: Subtask transform.fact_order_details.test
[2024-06-20T09:49:58.234+0000] {logging_mixin.py:188} WARNING - /home/airflow/.local/lib/python3.12/site-packages/airflow/settings.py:195 DeprecationWarning: The sql_alchemy_conn option in [core] has been moved to the sql_alchemy_conn option in [database] - the old setting has been used, but please update your config.
[2024-06-20T09:49:58.303+0000] {task_command.py:426} INFO - Running <TaskInstance: ELT-PROJECT.transform.fact_order_details.test manual__2024-06-20T09:44:25.931260+00:00 [running]> on host airflow-scheduler
[2024-06-20T09:49:58.546+0000] {taskinstance.py:2648} INFO - Exporting env vars: AIRFLOW_CTX_DAG_OWNER='Data-Ninja' AIRFLOW_CTX_DAG_ID='ELT-PROJECT' AIRFLOW_CTX_TASK_ID='transform.fact_order_details.test' AIRFLOW_CTX_EXECUTION_DATE='2024-06-20T09:44:25.931260+00:00' AIRFLOW_CTX_TRY_NUMBER='1' AIRFLOW_CTX_DAG_RUN_ID='manual__2024-06-20T09:44:25.931260+00:00'
[2024-06-20T09:49:58.549+0000] {taskinstance.py:430} INFO - ::endgroup::
[2024-06-20T09:49:58.570+0000] {local.py:174} INFO - Could not import dbtRunner. Falling back to subprocess for invoking dbt.
[2024-06-20T09:49:58.578+0000] {local.py:292} INFO - Cloning project to writable temp directory /tmp/tmp5k2j9gum from /opt/airflow/dags/dbt/dbt_project
[2024-06-20T09:49:58.591+0000] {local.py:303} INFO - Partial parse is enabled and the latest partial parse file is /tmp/cosmos/ELT-PROJECT__transform/target/partial_parse.msgpack
[2024-06-20T09:49:58.651+0000] {base.py:84} INFO - Using connection ID 'snow_conn' for task execution.
[2024-06-20T09:49:58.652+0000] {crypto.py:82} WARNING - empty cryptography key - values will not be stored encrypted.
[2024-06-20T09:49:58.656+0000] {base.py:225} INFO - Using real values for profile dbt_project
[2024-06-20T09:49:58.661+0000] {config.py:291} INFO - Creating temporary profiles.yml with use_mock_values=False at /tmp/tmpgvae_wu4/profiles.yml with the following contents:
dbt_project:
    outputs:
        dev:
            account: sk84886.europe-west2.gcp
            database: ELT_PROJECT
            password: '{{ env_var(''COSMOS_CONN_SNOWFLAKE_PASSWORD'') }}'
            role: SYSADMIN
            schema: PUBLIC
            type: snowflake
            user: DATANINJA
            warehouse: TRANSFORM
    target: dev

[2024-06-20T09:49:58.663+0000] {local.py:247} INFO - Trying to run the command:
 ['/opt/airflow/dbt_venv/bin/dbt', 'deps', '--project-dir', '/tmp/tmp5k2j9gum', '--profiles-dir', '/tmp/tmpgvae_wu4', '--profile', 'dbt_project', '--target', 'dev']
From /tmp/tmp5k2j9gum
[2024-06-20T09:49:58.666+0000] {subprocess.py:60} INFO - Tmp dir root location: 
 /tmp
[2024-06-20T09:49:58.667+0000] {subprocess.py:73} INFO - Running command: ['/opt/airflow/dbt_venv/bin/dbt', 'deps', '--project-dir', '/tmp/tmp5k2j9gum', '--profiles-dir', '/tmp/tmpgvae_wu4', '--profile', 'dbt_project', '--target', 'dev']
[2024-06-20T09:49:58.691+0000] {subprocess.py:84} INFO - Command output:
[2024-06-20T09:50:02.322+0000] {subprocess.py:94} INFO - [0m09:50:02  Running with dbt=1.8.2
[2024-06-20T09:50:02.664+0000] {subprocess.py:94} INFO - [0m09:50:02  Updating lock file in file path: /tmp/tmp5k2j9gum/package-lock.yml
[2024-06-20T09:50:02.684+0000] {subprocess.py:94} INFO - [0m09:50:02  Installing dbt-labs/dbt_utils
[2024-06-20T09:50:03.333+0000] {subprocess.py:94} INFO - [0m09:50:03  Installed from version 0.8.6
[2024-06-20T09:50:03.335+0000] {subprocess.py:94} INFO - [0m09:50:03  Updated version available: 1.2.0
[2024-06-20T09:50:03.338+0000] {subprocess.py:94} INFO - [0m09:50:03
[2024-06-20T09:50:03.340+0000] {subprocess.py:94} INFO - [0m09:50:03  Updates available for packages: ['dbt-labs/dbt_utils']
[2024-06-20T09:50:03.342+0000] {subprocess.py:94} INFO - Update your versions in packages.yml, then run dbt deps
[2024-06-20T09:50:04.662+0000] {subprocess.py:98} INFO - Command exited with return code 0
[2024-06-20T09:50:04.663+0000] {local.py:254} INFO - Update your versions in packages.yml, then run dbt deps
[2024-06-20T09:50:04.664+0000] {local.py:247} INFO - Trying to run the command:
 ['/opt/airflow/dbt_venv/bin/dbt', 'test', '--models', 'fact_order_details', '--project-dir', '/tmp/tmp5k2j9gum', '--profiles-dir', '/tmp/tmpgvae_wu4', '--profile', 'dbt_project', '--target', 'dev']
From /tmp/tmp5k2j9gum
[2024-06-20T09:50:04.666+0000] {subprocess.py:60} INFO - Tmp dir root location: 
 /tmp
[2024-06-20T09:50:04.667+0000] {subprocess.py:73} INFO - Running command: ['/opt/airflow/dbt_venv/bin/dbt', 'test', '--models', 'fact_order_details', '--project-dir', '/tmp/tmp5k2j9gum', '--profiles-dir', '/tmp/tmpgvae_wu4', '--profile', 'dbt_project', '--target', 'dev']
[2024-06-20T09:50:04.683+0000] {subprocess.py:84} INFO - Command output:
[2024-06-20T09:50:07.501+0000] {subprocess.py:94} INFO - [0m09:50:07  Running with dbt=1.8.2
[2024-06-20T09:50:08.138+0000] {subprocess.py:94} INFO - [0m09:50:08  Registered adapter: snowflake=1.8.3
[2024-06-20T09:50:09.749+0000] {subprocess.py:94} INFO - [0m09:50:09  Found 20 models, 28 data tests, 11 sources, 682 macros
[2024-06-20T09:50:09.753+0000] {subprocess.py:94} INFO - [0m09:50:09
[2024-06-20T09:50:15.042+0000] {subprocess.py:94} INFO - [0m09:50:15  Concurrency: 1 threads (target='dev')
[2024-06-20T09:50:15.044+0000] {subprocess.py:94} INFO - [0m09:50:15
[2024-06-20T09:50:15.062+0000] {subprocess.py:94} INFO - [0m09:50:15  1 of 4 START test not_null_fact_order_details_ORDERDETAILID .................... [RUN]
[2024-06-20T09:50:17.261+0000] {subprocess.py:94} INFO - [0m09:50:17  1 of 4 PASS not_null_fact_order_details_ORDERDETAILID .......................... [[32mPASS[0m in 2.20s]
[2024-06-20T09:50:17.269+0000] {subprocess.py:94} INFO - [0m09:50:17  2 of 4 START test not_null_fact_order_details_ORDERID .......................... [RUN]
[2024-06-20T09:50:18.972+0000] {subprocess.py:94} INFO - [0m09:50:18  2 of 4 PASS not_null_fact_order_details_ORDERID ................................ [[32mPASS[0m in 1.70s]
[2024-06-20T09:50:18.976+0000] {subprocess.py:94} INFO - [0m09:50:18  3 of 4 START test not_null_fact_order_details_PRODUCTID ........................ [RUN]
[2024-06-20T09:50:20.780+0000] {subprocess.py:94} INFO - [0m09:50:20  3 of 4 PASS not_null_fact_order_details_PRODUCTID .............................. [[32mPASS[0m in 1.80s]
[2024-06-20T09:50:20.784+0000] {subprocess.py:94} INFO - [0m09:50:20  4 of 4 START test unique_fact_order_details_ORDERDETAILID ...................... [RUN]
[2024-06-20T09:50:23.888+0000] {subprocess.py:94} INFO - [0m09:50:23  4 of 4 FAIL 693 unique_fact_order_details_ORDERDETAILID ........................ [[31mFAIL 693[0m in 3.10s]
[2024-06-20T09:50:23.899+0000] {subprocess.py:94} INFO - [0m09:50:23
[2024-06-20T09:50:23.902+0000] {subprocess.py:94} INFO - [0m09:50:23  Finished running 4 data tests in 0 hours 0 minutes and 14.14 seconds (14.14s).
[2024-06-20T09:50:24.107+0000] {subprocess.py:94} INFO - [0m09:50:24
[2024-06-20T09:50:24.108+0000] {subprocess.py:94} INFO - [0m09:50:24  [31mCompleted with 1 error and 0 warnings:[0m
[2024-06-20T09:50:24.110+0000] {subprocess.py:94} INFO - [0m09:50:24
[2024-06-20T09:50:24.112+0000] {subprocess.py:94} INFO - [0m09:50:24  [31mFailure in test unique_fact_order_details_ORDERDETAILID (models/warehouse/schema.yml)[0m
[2024-06-20T09:50:24.113+0000] {subprocess.py:94} INFO - [0m09:50:24    Got 693 results, configured to fail if != 0
[2024-06-20T09:50:24.115+0000] {subprocess.py:94} INFO - [0m09:50:24
[2024-06-20T09:50:24.116+0000] {subprocess.py:94} INFO - [0m09:50:24    compiled code at target/compiled/dbt_project/models/warehouse/schema.yml/unique_fact_order_details_ORDERDETAILID.sql
[2024-06-20T09:50:24.119+0000] {subprocess.py:94} INFO - [0m09:50:24
[2024-06-20T09:50:24.120+0000] {subprocess.py:94} INFO - [0m09:50:24  Done. PASS=3 WARN=0 ERROR=1 SKIP=0 TOTAL=4
[2024-06-20T09:50:25.814+0000] {subprocess.py:98} INFO - Command exited with return code 1
[2024-06-20T09:50:25.829+0000] {local.py:254} INFO - [0m09:50:24  Done. PASS=3 WARN=0 ERROR=1 SKIP=0 TOTAL=4
[2024-06-20T09:50:26.109+0000] {local.py:196} WARNING - Artifact schema version: https://schemas.getdbt.com/dbt/manifest/v12.json is above dbt-ol supported version 7. This might cause errors.
[2024-06-20T09:50:26.111+0000] {local.py:196} WARNING - Artifact schema version: https://schemas.getdbt.com/dbt/run-results/v6.json is above dbt-ol supported version 5. This might cause errors.
[2024-06-20T09:50:26.122+0000] {local.py:349} INFO - Inlets: [Dataset(uri='snowflake://sk84886.europe-west2.gcp/ELT_PROJECT.dwh.fact_order_details', extra=None)]
[2024-06-20T09:50:26.123+0000] {local.py:350} INFO - Outlets: []
[2024-06-20T09:50:26.124+0000] {dag.py:3096} INFO - Sync 1 DAGs
[2024-06-20T09:50:26.155+0000] {dag.py:3954} INFO - Setting next_dagrun for ELT-PROJECT to None, run_after=None
[2024-06-20T09:50:26.193+0000] {local.py:184} ERROR - [0m09:50:07  Running with dbt=1.8.2
[0m09:50:08  Registered adapter: snowflake=1.8.3
[0m09:50:09  Found 20 models, 28 data tests, 11 sources, 682 macros
[0m09:50:09
[0m09:50:15  Concurrency: 1 threads (target='dev')
[0m09:50:15
[0m09:50:15  1 of 4 START test not_null_fact_order_details_ORDERDETAILID .................... [RUN]
[0m09:50:17  1 of 4 PASS not_null_fact_order_details_ORDERDETAILID .......................... [[32mPASS[0m in 2.20s]
[0m09:50:17  2 of 4 START test not_null_fact_order_details_ORDERID .......................... [RUN]
[0m09:50:18  2 of 4 PASS not_null_fact_order_details_ORDERID ................................ [[32mPASS[0m in 1.70s]
[0m09:50:18  3 of 4 START test not_null_fact_order_details_PRODUCTID ........................ [RUN]
[0m09:50:20  3 of 4 PASS not_null_fact_order_details_PRODUCTID .............................. [[32mPASS[0m in 1.80s]
[0m09:50:20  4 of 4 START test unique_fact_order_details_ORDERDETAILID ...................... [RUN]
[0m09:50:23  4 of 4 FAIL 693 unique_fact_order_details_ORDERDETAILID ........................ [[31mFAIL 693[0m in 3.10s]
[0m09:50:23
[0m09:50:23  Finished running 4 data tests in 0 hours 0 minutes and 14.14 seconds (14.14s).
[0m09:50:24
[0m09:50:24  [31mCompleted with 1 error and 0 warnings:[0m
[0m09:50:24
[0m09:50:24  [31mFailure in test unique_fact_order_details_ORDERDETAILID (models/warehouse/schema.yml)[0m
[0m09:50:24    Got 693 results, configured to fail if != 0
[0m09:50:24
[0m09:50:24    compiled code at target/compiled/dbt_project/models/warehouse/schema.yml/unique_fact_order_details_ORDERDETAILID.sql
[0m09:50:24
[0m09:50:24  Done. PASS=3 WARN=0 ERROR=1 SKIP=0 TOTAL=4
[2024-06-20T09:50:26.208+0000] {taskinstance.py:441} INFO - ::group::Post task execution logs
[2024-06-20T09:50:26.226+0000] {taskinstance.py:2905} ERROR - Task failed with exception
Traceback (most recent call last):
  File "/home/airflow/.local/lib/python3.12/site-packages/airflow/models/taskinstance.py", line 465, in _execute_task
    result = _execute_callable(context=context, **execute_callable_kwargs)
             ^^^^^^^^^^^^^^^^^^^^^^^^^^^^^^^^^^^^^^^^^^^^^^^^^^^^^^^^^^^^^
  File "/home/airflow/.local/lib/python3.12/site-packages/airflow/models/taskinstance.py", line 432, in _execute_callable
    return execute_callable(context=context, **execute_callable_kwargs)
           ^^^^^^^^^^^^^^^^^^^^^^^^^^^^^^^^^^^^^^^^^^^^^^^^^^^^^^^^^^^^
  File "/home/airflow/.local/lib/python3.12/site-packages/airflow/models/baseoperator.py", line 401, in wrapper
    return func(self, *args, **kwargs)
           ^^^^^^^^^^^^^^^^^^^^^^^^^^^
  File "/home/airflow/.local/lib/python3.12/site-packages/cosmos/operators/local.py", line 579, in execute
    result = self.build_and_run_cmd(context=context, cmd_flags=self.add_cmd_flags())
             ^^^^^^^^^^^^^^^^^^^^^^^^^^^^^^^^^^^^^^^^^^^^^^^^^^^^^^^^^^^^^^^^^^^^^^^
  File "/home/airflow/.local/lib/python3.12/site-packages/cosmos/operators/local.py", line 489, in build_and_run_cmd
    result = self.run_command(cmd=dbt_cmd, env=env, context=context)
             ^^^^^^^^^^^^^^^^^^^^^^^^^^^^^^^^^^^^^^^^^^^^^^^^^^^^^^^
  File "/home/airflow/.local/lib/python3.12/site-packages/cosmos/operators/local.py", line 359, in run_command
    self.handle_exception(result)
  File "/home/airflow/.local/lib/python3.12/site-packages/cosmos/operators/local.py", line 185, in handle_exception_subprocess
    raise AirflowException(f"dbt command failed. The command returned a non-zero exit code {result.exit_code}.")
airflow.exceptions.AirflowException: dbt command failed. The command returned a non-zero exit code 1.
[2024-06-20T09:50:26.231+0000] {taskinstance.py:1206} INFO - Marking task as UP_FOR_RETRY. dag_id=ELT-PROJECT, task_id=transform.fact_order_details.test, run_id=manual__2024-06-20T09:44:25.931260+00:00, execution_date=20240620T094425, start_date=20240620T094958, end_date=20240620T095026
[2024-06-20T09:50:26.246+0000] {standard_task_runner.py:110} ERROR - Failed to execute job 498 for task transform.fact_order_details.test (dbt command failed. The command returned a non-zero exit code 1.; 8189)
[2024-06-20T09:50:26.296+0000] {local_task_job_runner.py:240} INFO - Task exited with return code 1
[2024-06-20T09:50:26.344+0000] {taskinstance.py:3503} INFO - 0 downstream tasks scheduled from follow-on schedule check
[2024-06-20T09:50:26.350+0000] {local_task_job_runner.py:222} INFO - ::endgroup::
