[2024-06-20T09:15:06.188+0000] {local_task_job_runner.py:120} INFO - ::group::Pre task execution logs
[2024-06-20T09:15:06.213+0000] {taskinstance.py:2076} INFO - Dependencies all met for dep_context=non-requeueable deps ti=<TaskInstance: ELT-PROJECT.transform.fact_order_details.test manual__2024-06-20T09:10:32.865792+00:00 [queued]>
[2024-06-20T09:15:06.226+0000] {taskinstance.py:2076} INFO - Dependencies all met for dep_context=requeueable deps ti=<TaskInstance: ELT-PROJECT.transform.fact_order_details.test manual__2024-06-20T09:10:32.865792+00:00 [queued]>
[2024-06-20T09:15:06.227+0000] {taskinstance.py:2306} INFO - Starting attempt 1 of 2
[2024-06-20T09:15:06.247+0000] {taskinstance.py:2330} INFO - Executing <Task(DbtTestLocalOperator): transform.fact_order_details.test> on 2024-06-20 09:10:32.865792+00:00
[2024-06-20T09:15:06.256+0000] {logging_mixin.py:188} WARNING - /home/airflow/.local/lib/python3.12/site-packages/airflow/task/task_runner/standard_task_runner.py:61 DeprecationWarning: This process (pid=5992) is multi-threaded, use of fork() may lead to deadlocks in the child.
[2024-06-20T09:15:06.257+0000] {standard_task_runner.py:63} INFO - Started process 5994 to run task
[2024-06-20T09:15:06.256+0000] {standard_task_runner.py:90} INFO - Running: ['airflow', 'tasks', 'run', 'ELT-PROJECT', 'transform.fact_order_details.test', 'manual__2024-06-20T09:10:32.865792+00:00', '--job-id', '383', '--raw', '--subdir', 'DAGS_FOLDER/elt.py', '--cfg-path', '/tmp/tmprmlim8of']
[2024-06-20T09:15:06.259+0000] {standard_task_runner.py:91} INFO - Job 383: Subtask transform.fact_order_details.test
[2024-06-20T09:15:06.279+0000] {logging_mixin.py:188} WARNING - /home/airflow/.local/lib/python3.12/site-packages/airflow/settings.py:195 DeprecationWarning: The sql_alchemy_conn option in [core] has been moved to the sql_alchemy_conn option in [database] - the old setting has been used, but please update your config.
[2024-06-20T09:15:06.322+0000] {task_command.py:426} INFO - Running <TaskInstance: ELT-PROJECT.transform.fact_order_details.test manual__2024-06-20T09:10:32.865792+00:00 [running]> on host airflow-scheduler
[2024-06-20T09:15:06.431+0000] {taskinstance.py:2648} INFO - Exporting env vars: AIRFLOW_CTX_DAG_OWNER='Data-Ninja' AIRFLOW_CTX_DAG_ID='ELT-PROJECT' AIRFLOW_CTX_TASK_ID='transform.fact_order_details.test' AIRFLOW_CTX_EXECUTION_DATE='2024-06-20T09:10:32.865792+00:00' AIRFLOW_CTX_TRY_NUMBER='1' AIRFLOW_CTX_DAG_RUN_ID='manual__2024-06-20T09:10:32.865792+00:00'
[2024-06-20T09:15:06.434+0000] {taskinstance.py:430} INFO - ::endgroup::
[2024-06-20T09:15:06.449+0000] {local.py:174} INFO - Could not import dbtRunner. Falling back to subprocess for invoking dbt.
[2024-06-20T09:15:06.451+0000] {local.py:292} INFO - Cloning project to writable temp directory /tmp/tmpsc3km6l1 from /opt/airflow/dags/dbt/dbt_project
[2024-06-20T09:15:06.461+0000] {local.py:303} INFO - Partial parse is enabled and the latest partial parse file is /tmp/cosmos/ELT-PROJECT__transform/target/partial_parse.msgpack
[2024-06-20T09:15:06.488+0000] {base.py:84} INFO - Using connection ID 'snow_conn' for task execution.
[2024-06-20T09:15:06.489+0000] {crypto.py:82} WARNING - empty cryptography key - values will not be stored encrypted.
[2024-06-20T09:15:06.490+0000] {base.py:225} INFO - Using real values for profile dbt_project
[2024-06-20T09:15:06.494+0000] {config.py:291} INFO - Creating temporary profiles.yml with use_mock_values=False at /tmp/tmprwf06lqy/profiles.yml with the following contents:
dbt_project:
    outputs:
        dev:
            account: sk84886.europe-west2.gcp
            database: ELT_PROJECT
            password: '{{ env_var(''COSMOS_CONN_SNOWFLAKE_PASSWORD'') }}'
            role: SYSADMIN
            schema: PUBLIC
            type: snowflake
            user: DATANINJA
            warehouse: TRANSFORM
    target: dev

[2024-06-20T09:15:06.495+0000] {local.py:247} INFO - Trying to run the command:
 ['/opt/airflow/dbt_venv/bin/dbt', 'deps', '--project-dir', '/tmp/tmpsc3km6l1', '--profiles-dir', '/tmp/tmprwf06lqy', '--profile', 'dbt_project', '--target', 'dev']
From /tmp/tmpsc3km6l1
[2024-06-20T09:15:06.497+0000] {subprocess.py:60} INFO - Tmp dir root location: 
 /tmp
[2024-06-20T09:15:06.498+0000] {subprocess.py:73} INFO - Running command: ['/opt/airflow/dbt_venv/bin/dbt', 'deps', '--project-dir', '/tmp/tmpsc3km6l1', '--profiles-dir', '/tmp/tmprwf06lqy', '--profile', 'dbt_project', '--target', 'dev']
[2024-06-20T09:15:06.511+0000] {subprocess.py:84} INFO - Command output:
[2024-06-20T09:15:08.740+0000] {subprocess.py:94} INFO - [0m09:15:08  Running with dbt=1.8.2
[2024-06-20T09:15:08.996+0000] {subprocess.py:94} INFO - [0m09:15:08  Updating lock file in file path: /tmp/tmpsc3km6l1/package-lock.yml
[2024-06-20T09:15:09.004+0000] {subprocess.py:94} INFO - [0m09:15:09  Installing dbt-labs/dbt_utils
[2024-06-20T09:15:09.515+0000] {subprocess.py:94} INFO - [0m09:15:09  Installed from version 0.8.6
[2024-06-20T09:15:09.516+0000] {subprocess.py:94} INFO - [0m09:15:09  Updated version available: 1.2.0
[2024-06-20T09:15:09.517+0000] {subprocess.py:94} INFO - [0m09:15:09
[2024-06-20T09:15:09.518+0000] {subprocess.py:94} INFO - [0m09:15:09  Updates available for packages: ['dbt-labs/dbt_utils']
[2024-06-20T09:15:09.519+0000] {subprocess.py:94} INFO - Update your versions in packages.yml, then run dbt deps
[2024-06-20T09:15:11.717+0000] {subprocess.py:98} INFO - Command exited with return code 0
[2024-06-20T09:15:11.718+0000] {local.py:254} INFO - Update your versions in packages.yml, then run dbt deps
[2024-06-20T09:15:11.720+0000] {local.py:247} INFO - Trying to run the command:
 ['/opt/airflow/dbt_venv/bin/dbt', 'test', '--models', 'fact_order_details', '--project-dir', '/tmp/tmpsc3km6l1', '--profiles-dir', '/tmp/tmprwf06lqy', '--profile', 'dbt_project', '--target', 'dev']
From /tmp/tmpsc3km6l1
[2024-06-20T09:15:11.721+0000] {subprocess.py:60} INFO - Tmp dir root location: 
 /tmp
[2024-06-20T09:15:11.722+0000] {subprocess.py:73} INFO - Running command: ['/opt/airflow/dbt_venv/bin/dbt', 'test', '--models', 'fact_order_details', '--project-dir', '/tmp/tmpsc3km6l1', '--profiles-dir', '/tmp/tmprwf06lqy', '--profile', 'dbt_project', '--target', 'dev']
[2024-06-20T09:15:11.737+0000] {subprocess.py:84} INFO - Command output:
[2024-06-20T09:15:13.924+0000] {subprocess.py:94} INFO - [0m09:15:13  Running with dbt=1.8.2
[2024-06-20T09:15:14.496+0000] {subprocess.py:94} INFO - [0m09:15:14  Registered adapter: snowflake=1.8.3
[2024-06-20T09:15:15.806+0000] {subprocess.py:94} INFO - [0m09:15:15  Found 20 models, 30 data tests, 11 sources, 682 macros
[2024-06-20T09:15:15.811+0000] {subprocess.py:94} INFO - [0m09:15:15
[2024-06-20T09:15:23.648+0000] {subprocess.py:94} INFO - [0m09:15:23  Concurrency: 1 threads (target='dev')
[2024-06-20T09:15:23.649+0000] {subprocess.py:94} INFO - [0m09:15:23
[2024-06-20T09:15:23.663+0000] {subprocess.py:94} INFO - [0m09:15:23  1 of 6 START test not_null_fact_order_details_ORDERDETAILID .................... [RUN]
[2024-06-20T09:15:25.325+0000] {subprocess.py:94} INFO - [0m09:15:25  1 of 6 PASS not_null_fact_order_details_ORDERDETAILID .......................... [[32mPASS[0m in 1.66s]
[2024-06-20T09:15:25.329+0000] {subprocess.py:94} INFO - [0m09:15:25  2 of 6 START test not_null_fact_order_details_ORDERID .......................... [RUN]
[2024-06-20T09:15:27.516+0000] {subprocess.py:94} INFO - [0m09:15:27  2 of 6 PASS not_null_fact_order_details_ORDERID ................................ [[32mPASS[0m in 2.18s]
[2024-06-20T09:15:27.520+0000] {subprocess.py:94} INFO - [0m09:15:27  3 of 6 START test not_null_fact_order_details_PRODUCTID ........................ [RUN]
[2024-06-20T09:15:29.678+0000] {subprocess.py:94} INFO - [0m09:15:29  3 of 6 PASS not_null_fact_order_details_PRODUCTID .............................. [[32mPASS[0m in 2.16s]
[2024-06-20T09:15:29.682+0000] {subprocess.py:94} INFO - [0m09:15:29  4 of 6 START test unique_fact_order_details_ORDERDETAILID ...................... [RUN]
[2024-06-20T09:15:31.768+0000] {subprocess.py:94} INFO - [0m09:15:31  4 of 6 FAIL 693 unique_fact_order_details_ORDERDETAILID ........................ [[31mFAIL 693[0m in 2.08s]
[2024-06-20T09:15:31.776+0000] {subprocess.py:94} INFO - [0m09:15:31  5 of 6 START test unique_fact_order_details_ORDERID ............................ [RUN]
[2024-06-20T09:15:33.637+0000] {subprocess.py:94} INFO - [0m09:15:33  5 of 6 FAIL 693 unique_fact_order_details_ORDERID .............................. [[31mFAIL 693[0m in 1.86s]
[2024-06-20T09:15:33.641+0000] {subprocess.py:94} INFO - [0m09:15:33  6 of 6 START test unique_fact_order_details_PRODUCTID .......................... [RUN]
[2024-06-20T09:15:36.669+0000] {subprocess.py:94} INFO - [0m09:15:36  6 of 6 FAIL 77 unique_fact_order_details_PRODUCTID ............................. [[31mFAIL 77[0m in 3.03s]
[2024-06-20T09:15:36.675+0000] {subprocess.py:94} INFO - [0m09:15:36
[2024-06-20T09:15:36.676+0000] {subprocess.py:94} INFO - [0m09:15:36  Finished running 6 data tests in 0 hours 0 minutes and 20.86 seconds (20.86s).
[2024-06-20T09:15:36.745+0000] {subprocess.py:94} INFO - [0m09:15:36
[2024-06-20T09:15:36.746+0000] {subprocess.py:94} INFO - [0m09:15:36  [31mCompleted with 3 errors and 0 warnings:[0m
[2024-06-20T09:15:36.747+0000] {subprocess.py:94} INFO - [0m09:15:36
[2024-06-20T09:15:36.748+0000] {subprocess.py:94} INFO - [0m09:15:36  [31mFailure in test unique_fact_order_details_ORDERDETAILID (models/warehouse/schema.yml)[0m
[2024-06-20T09:15:36.750+0000] {subprocess.py:94} INFO - [0m09:15:36    Got 693 results, configured to fail if != 0
[2024-06-20T09:15:36.751+0000] {subprocess.py:94} INFO - [0m09:15:36
[2024-06-20T09:15:36.753+0000] {subprocess.py:94} INFO - [0m09:15:36    compiled code at target/compiled/dbt_project/models/warehouse/schema.yml/unique_fact_order_details_ORDERDETAILID.sql
[2024-06-20T09:15:36.755+0000] {subprocess.py:94} INFO - [0m09:15:36
[2024-06-20T09:15:36.757+0000] {subprocess.py:94} INFO - [0m09:15:36  [31mFailure in test unique_fact_order_details_ORDERID (models/warehouse/schema.yml)[0m
[2024-06-20T09:15:36.759+0000] {subprocess.py:94} INFO - [0m09:15:36    Got 693 results, configured to fail if != 0
[2024-06-20T09:15:36.760+0000] {subprocess.py:94} INFO - [0m09:15:36
[2024-06-20T09:15:36.762+0000] {subprocess.py:94} INFO - [0m09:15:36    compiled code at target/compiled/dbt_project/models/warehouse/schema.yml/unique_fact_order_details_ORDERID.sql
[2024-06-20T09:15:36.763+0000] {subprocess.py:94} INFO - [0m09:15:36
[2024-06-20T09:15:36.764+0000] {subprocess.py:94} INFO - [0m09:15:36  [31mFailure in test unique_fact_order_details_PRODUCTID (models/warehouse/schema.yml)[0m
[2024-06-20T09:15:36.766+0000] {subprocess.py:94} INFO - [0m09:15:36    Got 77 results, configured to fail if != 0
[2024-06-20T09:15:36.767+0000] {subprocess.py:94} INFO - [0m09:15:36
[2024-06-20T09:15:36.768+0000] {subprocess.py:94} INFO - [0m09:15:36    compiled code at target/compiled/dbt_project/models/warehouse/schema.yml/unique_fact_order_details_PRODUCTID.sql
[2024-06-20T09:15:36.770+0000] {subprocess.py:94} INFO - [0m09:15:36
[2024-06-20T09:15:36.771+0000] {subprocess.py:94} INFO - [0m09:15:36  Done. PASS=3 WARN=0 ERROR=3 SKIP=0 TOTAL=6
[2024-06-20T09:15:38.259+0000] {subprocess.py:98} INFO - Command exited with return code 1
[2024-06-20T09:15:38.260+0000] {local.py:254} INFO - [0m09:15:36  Done. PASS=3 WARN=0 ERROR=3 SKIP=0 TOTAL=6
[2024-06-20T09:15:38.285+0000] {local.py:196} WARNING - Artifact schema version: https://schemas.getdbt.com/dbt/manifest/v12.json is above dbt-ol supported version 7. This might cause errors.
[2024-06-20T09:15:38.286+0000] {local.py:196} WARNING - Artifact schema version: https://schemas.getdbt.com/dbt/run-results/v6.json is above dbt-ol supported version 5. This might cause errors.
[2024-06-20T09:15:38.295+0000] {local.py:349} INFO - Inlets: [Dataset(uri='snowflake://sk84886.europe-west2.gcp/ELT_PROJECT.dwh.fact_order_details', extra=None)]
[2024-06-20T09:15:38.296+0000] {local.py:350} INFO - Outlets: []
[2024-06-20T09:15:38.298+0000] {dag.py:3096} INFO - Sync 1 DAGs
[2024-06-20T09:15:38.522+0000] {dag.py:3954} INFO - Setting next_dagrun for ELT-PROJECT to None, run_after=None
[2024-06-20T09:15:38.572+0000] {local.py:184} ERROR - [0m09:15:13  Running with dbt=1.8.2
[0m09:15:14  Registered adapter: snowflake=1.8.3
[0m09:15:15  Found 20 models, 30 data tests, 11 sources, 682 macros
[0m09:15:15
[0m09:15:23  Concurrency: 1 threads (target='dev')
[0m09:15:23
[0m09:15:23  1 of 6 START test not_null_fact_order_details_ORDERDETAILID .................... [RUN]
[0m09:15:25  1 of 6 PASS not_null_fact_order_details_ORDERDETAILID .......................... [[32mPASS[0m in 1.66s]
[0m09:15:25  2 of 6 START test not_null_fact_order_details_ORDERID .......................... [RUN]
[0m09:15:27  2 of 6 PASS not_null_fact_order_details_ORDERID ................................ [[32mPASS[0m in 2.18s]
[0m09:15:27  3 of 6 START test not_null_fact_order_details_PRODUCTID ........................ [RUN]
[0m09:15:29  3 of 6 PASS not_null_fact_order_details_PRODUCTID .............................. [[32mPASS[0m in 2.16s]
[0m09:15:29  4 of 6 START test unique_fact_order_details_ORDERDETAILID ...................... [RUN]
[0m09:15:31  4 of 6 FAIL 693 unique_fact_order_details_ORDERDETAILID ........................ [[31mFAIL 693[0m in 2.08s]
[0m09:15:31  5 of 6 START test unique_fact_order_details_ORDERID ............................ [RUN]
[0m09:15:33  5 of 6 FAIL 693 unique_fact_order_details_ORDERID .............................. [[31mFAIL 693[0m in 1.86s]
[0m09:15:33  6 of 6 START test unique_fact_order_details_PRODUCTID .......................... [RUN]
[0m09:15:36  6 of 6 FAIL 77 unique_fact_order_details_PRODUCTID ............................. [[31mFAIL 77[0m in 3.03s]
[0m09:15:36
[0m09:15:36  Finished running 6 data tests in 0 hours 0 minutes and 20.86 seconds (20.86s).
[0m09:15:36
[0m09:15:36  [31mCompleted with 3 errors and 0 warnings:[0m
[0m09:15:36
[0m09:15:36  [31mFailure in test unique_fact_order_details_ORDERDETAILID (models/warehouse/schema.yml)[0m
[0m09:15:36    Got 693 results, configured to fail if != 0
[0m09:15:36
[0m09:15:36    compiled code at target/compiled/dbt_project/models/warehouse/schema.yml/unique_fact_order_details_ORDERDETAILID.sql
[0m09:15:36
[0m09:15:36  [31mFailure in test unique_fact_order_details_ORDERID (models/warehouse/schema.yml)[0m
[0m09:15:36    Got 693 results, configured to fail if != 0
[0m09:15:36
[0m09:15:36    compiled code at target/compiled/dbt_project/models/warehouse/schema.yml/unique_fact_order_details_ORDERID.sql
[0m09:15:36
[0m09:15:36  [31mFailure in test unique_fact_order_details_PRODUCTID (models/warehouse/schema.yml)[0m
[0m09:15:36    Got 77 results, configured to fail if != 0
[0m09:15:36
[0m09:15:36    compiled code at target/compiled/dbt_project/models/warehouse/schema.yml/unique_fact_order_details_PRODUCTID.sql
[0m09:15:36
[0m09:15:36  Done. PASS=3 WARN=0 ERROR=3 SKIP=0 TOTAL=6
[2024-06-20T09:15:38.588+0000] {taskinstance.py:441} INFO - ::group::Post task execution logs
[2024-06-20T09:15:38.604+0000] {taskinstance.py:2905} ERROR - Task failed with exception
Traceback (most recent call last):
  File "/home/airflow/.local/lib/python3.12/site-packages/airflow/models/taskinstance.py", line 465, in _execute_task
    result = _execute_callable(context=context, **execute_callable_kwargs)
             ^^^^^^^^^^^^^^^^^^^^^^^^^^^^^^^^^^^^^^^^^^^^^^^^^^^^^^^^^^^^^
  File "/home/airflow/.local/lib/python3.12/site-packages/airflow/models/taskinstance.py", line 432, in _execute_callable
    return execute_callable(context=context, **execute_callable_kwargs)
           ^^^^^^^^^^^^^^^^^^^^^^^^^^^^^^^^^^^^^^^^^^^^^^^^^^^^^^^^^^^^
  File "/home/airflow/.local/lib/python3.12/site-packages/airflow/models/baseoperator.py", line 401, in wrapper
    return func(self, *args, **kwargs)
           ^^^^^^^^^^^^^^^^^^^^^^^^^^^
  File "/home/airflow/.local/lib/python3.12/site-packages/cosmos/operators/local.py", line 579, in execute
    result = self.build_and_run_cmd(context=context, cmd_flags=self.add_cmd_flags())
             ^^^^^^^^^^^^^^^^^^^^^^^^^^^^^^^^^^^^^^^^^^^^^^^^^^^^^^^^^^^^^^^^^^^^^^^
  File "/home/airflow/.local/lib/python3.12/site-packages/cosmos/operators/local.py", line 489, in build_and_run_cmd
    result = self.run_command(cmd=dbt_cmd, env=env, context=context)
             ^^^^^^^^^^^^^^^^^^^^^^^^^^^^^^^^^^^^^^^^^^^^^^^^^^^^^^^
  File "/home/airflow/.local/lib/python3.12/site-packages/cosmos/operators/local.py", line 359, in run_command
    self.handle_exception(result)
  File "/home/airflow/.local/lib/python3.12/site-packages/cosmos/operators/local.py", line 185, in handle_exception_subprocess
    raise AirflowException(f"dbt command failed. The command returned a non-zero exit code {result.exit_code}.")
airflow.exceptions.AirflowException: dbt command failed. The command returned a non-zero exit code 1.
[2024-06-20T09:15:38.609+0000] {taskinstance.py:1206} INFO - Marking task as UP_FOR_RETRY. dag_id=ELT-PROJECT, task_id=transform.fact_order_details.test, run_id=manual__2024-06-20T09:10:32.865792+00:00, execution_date=20240620T091032, start_date=20240620T091506, end_date=20240620T091538
[2024-06-20T09:15:38.623+0000] {standard_task_runner.py:110} ERROR - Failed to execute job 383 for task transform.fact_order_details.test (dbt command failed. The command returned a non-zero exit code 1.; 5994)
[2024-06-20T09:15:38.663+0000] {local_task_job_runner.py:240} INFO - Task exited with return code 1
[2024-06-20T09:15:38.713+0000] {taskinstance.py:3503} INFO - 0 downstream tasks scheduled from follow-on schedule check
[2024-06-20T09:15:38.716+0000] {local_task_job_runner.py:222} INFO - ::endgroup::
