[2024-06-17T11:55:14.684+0000] {local_task_job_runner.py:120} INFO - ::group::Pre task execution logs
[2024-06-17T11:55:14.797+0000] {taskinstance.py:2076} INFO - Dependencies all met for dep_context=non-requeueable deps ti=<TaskInstance: ELT-PROJECT.load_process.load_categories manual__2024-06-17T11:54:58.411739+00:00 [queued]>
[2024-06-17T11:55:14.841+0000] {taskinstance.py:2076} INFO - Dependencies all met for dep_context=requeueable deps ti=<TaskInstance: ELT-PROJECT.load_process.load_categories manual__2024-06-17T11:54:58.411739+00:00 [queued]>
[2024-06-17T11:55:14.844+0000] {taskinstance.py:2306} INFO - Starting attempt 1 of 2
[2024-06-17T11:55:14.895+0000] {taskinstance.py:2330} INFO - Executing <Task(_PythonDecoratedOperator): load_process.load_categories> on 2024-06-17 11:54:58.411739+00:00
[2024-06-17T11:55:14.924+0000] {logging_mixin.py:188} WARNING - /home/airflow/.local/lib/python3.12/site-packages/airflow/task/task_runner/standard_task_runner.py:61 DeprecationWarning: This process (pid=2173) is multi-threaded, use of fork() may lead to deadlocks in the child.
[2024-06-17T11:55:14.924+0000] {standard_task_runner.py:90} INFO - Running: ['airflow', 'tasks', 'run', 'ELT-PROJECT', 'load_process.load_categories', 'manual__2024-06-17T11:54:58.411739+00:00', '--job-id', '251', '--raw', '--subdir', 'DAGS_FOLDER/elt.py', '--cfg-path', '/tmp/tmph7vbl7am']
[2024-06-17T11:55:14.934+0000] {standard_task_runner.py:63} INFO - Started process 2207 to run task
[2024-06-17T11:55:14.935+0000] {standard_task_runner.py:91} INFO - Job 251: Subtask load_process.load_categories
[2024-06-17T11:55:15.017+0000] {logging_mixin.py:188} WARNING - /home/airflow/.local/lib/python3.12/site-packages/airflow/settings.py:195 DeprecationWarning: The sql_alchemy_conn option in [core] has been moved to the sql_alchemy_conn option in [database] - the old setting has been used, but please update your config.
[2024-06-17T11:55:15.160+0000] {task_command.py:426} INFO - Running <TaskInstance: ELT-PROJECT.load_process.load_categories manual__2024-06-17T11:54:58.411739+00:00 [running]> on host airflow-scheduler
[2024-06-17T11:55:15.939+0000] {taskinstance.py:2648} INFO - Exporting env vars: AIRFLOW_CTX_DAG_OWNER='Data-Ninja' AIRFLOW_CTX_DAG_ID='ELT-PROJECT' AIRFLOW_CTX_TASK_ID='load_process.load_categories' AIRFLOW_CTX_EXECUTION_DATE='2024-06-17T11:54:58.411739+00:00' AIRFLOW_CTX_TRY_NUMBER='1' AIRFLOW_CTX_DAG_RUN_ID='manual__2024-06-17T11:54:58.411739+00:00'
[2024-06-17T11:55:15.947+0000] {taskinstance.py:430} INFO - ::endgroup::
[2024-06-17T11:55:15.951+0000] {connection.py:399} INFO - Snowflake Connector for Python Version: 3.10.1, Python Version: 3.12.4, Platform: Linux-5.15.133.1-microsoft-standard-WSL2-x86_64-with-glibc2.36
[2024-06-17T11:55:15.955+0000] {connection.py:1249} INFO - THIS CONNECTION IS IN INSECURE MODE. IT MEANS THE CERTIFICATE WILL BE VALIDATED BUT THE CERTIFICATE REVOCATION STATUS WILL NOT BE CHECKED.
[2024-06-17T11:55:16.344+0000] {ssl_wrap_socket.py:100} INFO - THIS CONNECTION IS IN INSECURE MODE. IT MEANS THE CERTIFICATE WILL BE VALIDATED BUT THE CERTIFICATE REVOCATION STATUS WILL NOT BE CHECKED.
[2024-06-17T11:55:17.027+0000] {logging_mixin.py:188} INFO - Nama kolom di DataFrame: Index(['territoryID', 'territoryDescription', 'regionID'], dtype='object')
[2024-06-17T11:55:17.447+0000] {cursor.py:1149} INFO - Number of results in first chunk: 1
[2024-06-17T11:55:18.190+0000] {ssl_wrap_socket.py:100} INFO - THIS CONNECTION IS IN INSECURE MODE. IT MEANS THE CERTIFICATE WILL BE VALIDATED BUT THE CERTIFICATE REVOCATION STATUS WILL NOT BE CHECKED.
[2024-06-17T11:55:20.981+0000] {cursor.py:1149} INFO - Number of results in first chunk: 1
[2024-06-17T11:55:21.647+0000] {cursor.py:1149} INFO - Number of results in first chunk: 3
[2024-06-17T11:55:22.031+0000] {cursor.py:1149} INFO - Number of results in first chunk: 1
[2024-06-17T11:55:22.459+0000] {cursor.py:1149} INFO - Number of results in first chunk: 1
[2024-06-17T11:55:22.885+0000] {taskinstance.py:441} INFO - ::group::Post task execution logs
[2024-06-17T11:55:22.888+0000] {taskinstance.py:2905} ERROR - Task failed with exception
Traceback (most recent call last):
  File "/home/airflow/.local/lib/python3.12/site-packages/airflow/models/taskinstance.py", line 465, in _execute_task
    result = _execute_callable(context=context, **execute_callable_kwargs)
             ^^^^^^^^^^^^^^^^^^^^^^^^^^^^^^^^^^^^^^^^^^^^^^^^^^^^^^^^^^^^^
  File "/home/airflow/.local/lib/python3.12/site-packages/airflow/models/taskinstance.py", line 432, in _execute_callable
    return execute_callable(context=context, **execute_callable_kwargs)
           ^^^^^^^^^^^^^^^^^^^^^^^^^^^^^^^^^^^^^^^^^^^^^^^^^^^^^^^^^^^^
  File "/home/airflow/.local/lib/python3.12/site-packages/airflow/models/baseoperator.py", line 401, in wrapper
    return func(self, *args, **kwargs)
           ^^^^^^^^^^^^^^^^^^^^^^^^^^^
  File "/home/airflow/.local/lib/python3.12/site-packages/airflow/decorators/base.py", line 265, in execute
    return_value = super().execute(context)
                   ^^^^^^^^^^^^^^^^^^^^^^^^
  File "/home/airflow/.local/lib/python3.12/site-packages/airflow/models/baseoperator.py", line 401, in wrapper
    return func(self, *args, **kwargs)
           ^^^^^^^^^^^^^^^^^^^^^^^^^^^
  File "/home/airflow/.local/lib/python3.12/site-packages/airflow/operators/python.py", line 235, in execute
    return_value = self.execute_callable()
                   ^^^^^^^^^^^^^^^^^^^^^^^
  File "/home/airflow/.local/lib/python3.12/site-packages/airflow/operators/python.py", line 252, in execute_callable
    return self.python_callable(*self.op_args, **self.op_kwargs)
           ^^^^^^^^^^^^^^^^^^^^^^^^^^^^^^^^^^^^^^^^^^^^^^^^^^^^^
  File "/opt/airflow/dags/elt.py", line 67, in load
    load_func(df=df, table_names=table)
  File "/local_module/loaders.py", line 34, in load_func
    write_pandas(
  File "/home/airflow/.local/lib/python3.12/site-packages/snowflake/connector/pandas_tools.py", line 438, in write_pandas
    copy_results = cursor.execute(copy_into_sql, _is_internal=True).fetchall()
                   ^^^^^^^^^^^^^^^^^^^^^^^^^^^^^^^^^^^^^^^^^^^^^^^^
  File "/home/airflow/.local/lib/python3.12/site-packages/snowflake/connector/cursor.py", line 1080, in execute
    Error.errorhandler_wrapper(self.connection, self, error_class, errvalue)
  File "/home/airflow/.local/lib/python3.12/site-packages/snowflake/connector/errors.py", line 290, in errorhandler_wrapper
    handed_over = Error.hand_to_other_handler(
                  ^^^^^^^^^^^^^^^^^^^^^^^^^^^^
  File "/home/airflow/.local/lib/python3.12/site-packages/snowflake/connector/errors.py", line 345, in hand_to_other_handler
    cursor.errorhandler(connection, cursor, error_class, error_value)
  File "/home/airflow/.local/lib/python3.12/site-packages/snowflake/connector/errors.py", line 221, in default_errorhandler
    raise error_class(
snowflake.connector.errors.ProgrammingError: 000904 (42000): 01b511ab-0000-8bb0-0000-ec9500044be2: SQL compilation error: error line 1 at position 83
invalid identifier 'TERRITORYID'
[2024-06-17T11:55:22.923+0000] {taskinstance.py:1206} INFO - Marking task as UP_FOR_RETRY. dag_id=ELT-PROJECT, task_id=load_process.load_categories, run_id=manual__2024-06-17T11:54:58.411739+00:00, execution_date=20240617T115458, start_date=20240617T115514, end_date=20240617T115522
[2024-06-17T11:55:22.956+0000] {standard_task_runner.py:110} ERROR - Failed to execute job 251 for task load_process.load_categories (000904 (42000): 01b511ab-0000-8bb0-0000-ec9500044be2: SQL compilation error: error line 1 at position 83
invalid identifier 'TERRITORYID'; 2207)
[2024-06-17T11:55:23.040+0000] {local_task_job_runner.py:240} INFO - Task exited with return code 1
[2024-06-17T11:55:23.085+0000] {local_task_job_runner.py:222} INFO - ::endgroup::
