[2024-06-17T12:00:26.285+0000] {local_task_job_runner.py:120} INFO - ::group::Pre task execution logs
[2024-06-17T12:00:26.395+0000] {taskinstance.py:2076} INFO - Dependencies all met for dep_context=non-requeueable deps ti=<TaskInstance: ELT-PROJECT.load_process.load_orders manual__2024-06-17T11:54:58.411739+00:00 [queued]>
[2024-06-17T12:00:26.425+0000] {taskinstance.py:2076} INFO - Dependencies all met for dep_context=requeueable deps ti=<TaskInstance: ELT-PROJECT.load_process.load_orders manual__2024-06-17T11:54:58.411739+00:00 [queued]>
[2024-06-17T12:00:26.427+0000] {taskinstance.py:2306} INFO - Starting attempt 2 of 2
[2024-06-17T12:00:26.476+0000] {taskinstance.py:2330} INFO - Executing <Task(_PythonDecoratedOperator): load_process.load_orders> on 2024-06-17 11:54:58.411739+00:00
[2024-06-17T12:00:26.510+0000] {logging_mixin.py:188} WARNING - /home/airflow/.local/lib/python3.12/site-packages/airflow/task/task_runner/standard_task_runner.py:61 DeprecationWarning: This process (pid=2367) is multi-threaded, use of fork() may lead to deadlocks in the child.
[2024-06-17T12:00:26.516+0000] {standard_task_runner.py:63} INFO - Started process 2396 to run task
[2024-06-17T12:00:26.522+0000] {standard_task_runner.py:90} INFO - Running: ['airflow', 'tasks', 'run', 'ELT-PROJECT', 'load_process.load_orders', 'manual__2024-06-17T11:54:58.411739+00:00', '--job-id', '263', '--raw', '--subdir', 'DAGS_FOLDER/elt.py', '--cfg-path', '/tmp/tmpafq5axge']
[2024-06-17T12:00:26.529+0000] {standard_task_runner.py:91} INFO - Job 263: Subtask load_process.load_orders
[2024-06-17T12:00:26.644+0000] {logging_mixin.py:188} WARNING - /home/airflow/.local/lib/python3.12/site-packages/airflow/settings.py:195 DeprecationWarning: The sql_alchemy_conn option in [core] has been moved to the sql_alchemy_conn option in [database] - the old setting has been used, but please update your config.
[2024-06-17T12:00:26.804+0000] {task_command.py:426} INFO - Running <TaskInstance: ELT-PROJECT.load_process.load_orders manual__2024-06-17T11:54:58.411739+00:00 [running]> on host airflow-scheduler
[2024-06-17T12:00:27.433+0000] {taskinstance.py:2648} INFO - Exporting env vars: AIRFLOW_CTX_DAG_OWNER='Data-Ninja' AIRFLOW_CTX_DAG_ID='ELT-PROJECT' AIRFLOW_CTX_TASK_ID='load_process.load_orders' AIRFLOW_CTX_EXECUTION_DATE='2024-06-17T11:54:58.411739+00:00' AIRFLOW_CTX_TRY_NUMBER='2' AIRFLOW_CTX_DAG_RUN_ID='manual__2024-06-17T11:54:58.411739+00:00'
[2024-06-17T12:00:27.439+0000] {taskinstance.py:430} INFO - ::endgroup::
[2024-06-17T12:00:27.442+0000] {connection.py:399} INFO - Snowflake Connector for Python Version: 3.10.1, Python Version: 3.12.4, Platform: Linux-5.15.133.1-microsoft-standard-WSL2-x86_64-with-glibc2.36
[2024-06-17T12:00:27.444+0000] {connection.py:1249} INFO - THIS CONNECTION IS IN INSECURE MODE. IT MEANS THE CERTIFICATE WILL BE VALIDATED BUT THE CERTIFICATE REVOCATION STATUS WILL NOT BE CHECKED.
[2024-06-17T12:00:27.741+0000] {ssl_wrap_socket.py:100} INFO - THIS CONNECTION IS IN INSECURE MODE. IT MEANS THE CERTIFICATE WILL BE VALIDATED BUT THE CERTIFICATE REVOCATION STATUS WILL NOT BE CHECKED.
[2024-06-17T12:00:28.314+0000] {logging_mixin.py:188} INFO - Nama kolom di DataFrame: Index(['territoryID', 'territoryDescription', 'regionID'], dtype='object')
[2024-06-17T12:00:28.716+0000] {cursor.py:1149} INFO - Number of results in first chunk: 1
[2024-06-17T12:00:29.396+0000] {ssl_wrap_socket.py:100} INFO - THIS CONNECTION IS IN INSECURE MODE. IT MEANS THE CERTIFICATE WILL BE VALIDATED BUT THE CERTIFICATE REVOCATION STATUS WILL NOT BE CHECKED.
[2024-06-17T12:00:31.782+0000] {cursor.py:1149} INFO - Number of results in first chunk: 1
[2024-06-17T12:00:32.706+0000] {cursor.py:1149} INFO - Number of results in first chunk: 3
[2024-06-17T12:00:33.078+0000] {cursor.py:1149} INFO - Number of results in first chunk: 1
[2024-06-17T12:00:33.540+0000] {cursor.py:1149} INFO - Number of results in first chunk: 1
[2024-06-17T12:00:33.928+0000] {taskinstance.py:441} INFO - ::group::Post task execution logs
[2024-06-17T12:00:33.929+0000] {taskinstance.py:2905} ERROR - Task failed with exception
Traceback (most recent call last):
  File "/home/airflow/.local/lib/python3.12/site-packages/airflow/models/taskinstance.py", line 465, in _execute_task
    result = _execute_callable(context=context, **execute_callable_kwargs)
             ^^^^^^^^^^^^^^^^^^^^^^^^^^^^^^^^^^^^^^^^^^^^^^^^^^^^^^^^^^^^^
  File "/home/airflow/.local/lib/python3.12/site-packages/airflow/models/taskinstance.py", line 432, in _execute_callable
    return execute_callable(context=context, **execute_callable_kwargs)
           ^^^^^^^^^^^^^^^^^^^^^^^^^^^^^^^^^^^^^^^^^^^^^^^^^^^^^^^^^^^^
  File "/home/airflow/.local/lib/python3.12/site-packages/airflow/models/baseoperator.py", line 401, in wrapper
    return func(self, *args, **kwargs)
           ^^^^^^^^^^^^^^^^^^^^^^^^^^^
  File "/home/airflow/.local/lib/python3.12/site-packages/airflow/decorators/base.py", line 265, in execute
    return_value = super().execute(context)
                   ^^^^^^^^^^^^^^^^^^^^^^^^
  File "/home/airflow/.local/lib/python3.12/site-packages/airflow/models/baseoperator.py", line 401, in wrapper
    return func(self, *args, **kwargs)
           ^^^^^^^^^^^^^^^^^^^^^^^^^^^
  File "/home/airflow/.local/lib/python3.12/site-packages/airflow/operators/python.py", line 235, in execute
    return_value = self.execute_callable()
                   ^^^^^^^^^^^^^^^^^^^^^^^
  File "/home/airflow/.local/lib/python3.12/site-packages/airflow/operators/python.py", line 252, in execute_callable
    return self.python_callable(*self.op_args, **self.op_kwargs)
           ^^^^^^^^^^^^^^^^^^^^^^^^^^^^^^^^^^^^^^^^^^^^^^^^^^^^^
  File "/opt/airflow/dags/elt.py", line 67, in load
    load_func(df=df, table_names=table)
  File "/local_module/loaders.py", line 34, in load_func
    write_pandas(
  File "/home/airflow/.local/lib/python3.12/site-packages/snowflake/connector/pandas_tools.py", line 438, in write_pandas
    copy_results = cursor.execute(copy_into_sql, _is_internal=True).fetchall()
                   ^^^^^^^^^^^^^^^^^^^^^^^^^^^^^^^^^^^^^^^^^^^^^^^^
  File "/home/airflow/.local/lib/python3.12/site-packages/snowflake/connector/cursor.py", line 1080, in execute
    Error.errorhandler_wrapper(self.connection, self, error_class, errvalue)
  File "/home/airflow/.local/lib/python3.12/site-packages/snowflake/connector/errors.py", line 290, in errorhandler_wrapper
    handed_over = Error.hand_to_other_handler(
                  ^^^^^^^^^^^^^^^^^^^^^^^^^^^^
  File "/home/airflow/.local/lib/python3.12/site-packages/snowflake/connector/errors.py", line 345, in hand_to_other_handler
    cursor.errorhandler(connection, cursor, error_class, error_value)
  File "/home/airflow/.local/lib/python3.12/site-packages/snowflake/connector/errors.py", line 221, in default_errorhandler
    raise error_class(
snowflake.connector.errors.ProgrammingError: 000904 (42000): 01b511b0-0000-8bb0-0000-ec9500044c5e: SQL compilation error: error line 1 at position 79
invalid identifier 'TERRITORYID'
[2024-06-17T12:00:33.971+0000] {taskinstance.py:222} INFO - Forcing task load_process.load_shippers to fail due to dag's `fail_stop` setting
[2024-06-17T12:00:33.973+0000] {taskinstance.py:1774} ERROR - Recording the task instance as FAILED
[2024-06-17T12:00:33.992+0000] {taskinstance.py:222} INFO - Forcing task load_process.load_products to fail due to dag's `fail_stop` setting
[2024-06-17T12:00:33.993+0000] {taskinstance.py:1774} ERROR - Recording the task instance as FAILED
[2024-06-17T12:00:34.023+0000] {taskinstance.py:222} INFO - Forcing task load_process.load_customers to fail due to dag's `fail_stop` setting
[2024-06-17T12:00:34.024+0000] {taskinstance.py:1774} ERROR - Recording the task instance as FAILED
[2024-06-17T12:00:34.058+0000] {taskinstance.py:222} INFO - Forcing task load_process.load_employee_territories to fail due to dag's `fail_stop` setting
[2024-06-17T12:00:34.060+0000] {taskinstance.py:1774} ERROR - Recording the task instance as FAILED
[2024-06-17T12:00:34.093+0000] {taskinstance.py:222} INFO - Forcing task load_process.load_suppliers to fail due to dag's `fail_stop` setting
[2024-06-17T12:00:34.095+0000] {taskinstance.py:1774} ERROR - Recording the task instance as FAILED
[2024-06-17T12:00:34.136+0000] {taskinstance.py:222} INFO - Forcing task load_process.load_territories to fail due to dag's `fail_stop` setting
[2024-06-17T12:00:34.138+0000] {taskinstance.py:1774} ERROR - Recording the task instance as FAILED
[2024-06-17T12:00:34.184+0000] {taskinstance.py:222} INFO - Forcing task load_process.load_order_details to fail due to dag's `fail_stop` setting
[2024-06-17T12:00:34.185+0000] {taskinstance.py:1774} ERROR - Recording the task instance as FAILED
[2024-06-17T12:00:34.214+0000] {taskinstance.py:222} INFO - Forcing task load_process.load_categories to fail due to dag's `fail_stop` setting
[2024-06-17T12:00:34.215+0000] {taskinstance.py:1774} ERROR - Recording the task instance as FAILED
[2024-06-17T12:00:34.284+0000] {taskinstance.py:222} INFO - Forcing task load_process.load_employees to fail due to dag's `fail_stop` setting
[2024-06-17T12:00:34.288+0000] {taskinstance.py:1774} ERROR - Recording the task instance as FAILED
[2024-06-17T12:00:34.343+0000] {taskinstance.py:222} INFO - Forcing task load_process.load_regions to fail due to dag's `fail_stop` setting
[2024-06-17T12:00:34.348+0000] {taskinstance.py:1774} ERROR - Recording the task instance as FAILED
[2024-06-17T12:00:34.402+0000] {taskinstance.py:1206} INFO - Marking task as FAILED. dag_id=ELT-PROJECT, task_id=load_process.load_orders, run_id=manual__2024-06-17T11:54:58.411739+00:00, execution_date=20240617T115458, start_date=20240617T120026, end_date=20240617T120033
[2024-06-17T12:00:34.454+0000] {standard_task_runner.py:110} ERROR - Failed to execute job 263 for task load_process.load_orders (000904 (42000): 01b511b0-0000-8bb0-0000-ec9500044c5e: SQL compilation error: error line 1 at position 79
invalid identifier 'TERRITORYID'; 2396)
[2024-06-17T12:00:34.487+0000] {local_task_job_runner.py:240} INFO - Task exited with return code 1
[2024-06-17T12:00:34.563+0000] {taskinstance.py:3503} INFO - 0 downstream tasks scheduled from follow-on schedule check
[2024-06-17T12:00:34.583+0000] {local_task_job_runner.py:222} INFO - ::endgroup::
